Workbook

Sheet Task Plan
A1: Senpai MVP — Task Plan Coding
A2: File quản lý đầu task coding cho MVP static web: Landing → Lesson → Progress → Quiz → Flashcard → Polish
A4: ID | B4: Sprint | C4: Nhóm function | D4: Module/Trang | E4: Đầu task coding | F4: Mô tả chi tiết | G4: Priority | H4: Owner | I4: Status | J4: Start Date | K4: Due Date | L4: Est. Days | M4: Progress % | N4: Dependency | O4: Deliverable | P4: Notes
A5: T001 | B5: Sprint 1 | C5: Setup | D5: Project Structure | E5: Tạo folder structure Senpai | F5: Tạo đầy đủ folder japanese, stage, assets, docs theo cấu trúc dự án. | G5: High | H5: FE Dev | I5: Done | J5: 46146 | K5: 46146 | L5: 0.5 | M5: 1 | O5: Folder project
A6: T002 | B6: Sprint 1 | C6: Setup | D6: Project Structure | E6: Tạo file CSS/JS rỗng ban đầu | F6: Tạo main.css, components.css, lesson.css, progress.js, quiz.js, flashcard.js, theme.js. | G6: High | H6: FE Dev | I6: Done | J6: 46147 | K6: 46147 | L6: 0.5 | M6: 1 | N6: T001 | O6: Skeleton assets
A7: T003 | B7: Sprint 1 | C7: Landing | D7: index.html | E7: Tạo layout landing page | F7: Hero, đối tượng học, lời hứa giá trị, CTA bắt đầu học. | G7: High | H7: FE Dev | I7: Done | J7: 46148 | K7: 46148 | L7: 1 | M7: 1 | N7: T001 | O7: Landing page
A8: T004 | B8: Sprint 1 | C8: Landing | D8: index.html | E8: Viết nội dung landing page | F8: Nội dung ngắn gọn cho Senpai: tiếng Nhật công sở thực chiến cho IT Nhật. | G8: High | H8: Content | I8: Done | J8: 46149 | K8: 46149 | L8: 0.5 | M8: 1 | N8: T003 | O8: Landing copy
A9: T005 | B9: Sprint 1 | C9: UI Component | D9: Header/Footer | E9: Tạo global header và footer | F9: Header có logo, menu, CTA; footer có thông tin dự án. | G9: Medium | H9: FE Dev | I9: Done | J9: 46150 | K9: 46150 | L9: 0.5 | M9: 1 | N9: T003 | O9: Header/footer
A10: T006 | B10: Sprint 1 | C10: Japanese Hub | D10: japanese/index.html | E10: Tạo Japanese Hub | F10: Trang chọn giai đoạn học Stage 1-4. | G10: High | H10: FE Dev | I10: Done | J10: 46151 | K10: 46151 | L10: 1 | M10: 1 | N10: T001 | O10: Hub page
A11: T007 | B11: Sprint 1 | C11: Japanese Hub | D11: Stage Cards | E11: Tạo card cho 4 stage | F11: Mỗi card có tên stage, mô tả, số module, progress placeholder. | G11: High | H11: FE Dev | I11: Done | J11: 46152 | K11: 46152 | L11: 1 | M11: 1 | N11: T006 | O11: Stage cards
A12: T008 | B12: Sprint 1 | C12: Stage Page | D12: stage index | E12: Tạo 4 trang stage index | F12: Tạo stage1/index.html đến stage4/index.html. | G12: High | H12: FE Dev | I12: Done | J12: 46153 | K12: 46153 | L12: 1 | M12: 1 | N12: T001 | O12: Stage pages
A13: T009 | B13: Sprint 1 | C13: Stage 2 | D13: stage2/index.html | E13: Tạo module list Stage 2 | F13: Hiển thị Email, Meeting, Reporting, Keigo, Grammar, Reception. | G13: High | H13: FE Dev | I13: Done | J13: 46154 | K13: 46154 | L13: 1 | M13: 1 | N13: T008 | O13: Stage2 module list
A14: T010 | B14: Sprint 1 | C14: Deploy | D14: GitHub Pages | E14: Deploy GitHub Pages lần 1 | F14: Đưa bản khung website lên GitHub Pages để xem demo. | G14: High | H14: FE Dev | I14: Done | J14: 46155 | K14: 46155 | L14: 0.5 | M14: 1 | N14: T003,T006,T008 | O14: Demo URL
A15: T011 | B15: Sprint 2 | C15: Lesson Template | D15: docs/lesson-template.md | E15: Tạo lesson template chuẩn | F15: Định nghĩa cấu trúc Hero, Video, Notes, Vocab, Pattern, Example, Practice, Quiz, Nav. | G15: High | H15: PM | I15: In Progress | J15: 46156 | K15: 46156 | L15: 0.5 | M15: 0.5 | O15: Lesson template
A16: T012 | B16: Sprint 2 | C16: Lesson UI | D16: lesson.css | E16: Style lesson container | F16: CSS cho bài học, spacing, typography, Japanese block, Vietnamese note. | G16: High | H16: FE Dev | I16: Not Started | J16: 46157 | K16: 46157 | L16: 1 | M16: =IF(I16="Done",1,IF(I16="Review",0.8,IF(I16="In Progress",0.5,0))) | N16: T011 | O16: Lesson style
A17: T013 | B17: Sprint 2 | C17: Video | D17: Lesson Video Block | E17: Tạo video placeholder | F17: Khi chưa có video thì hiển thị thumbnail giả + text thông báo. | G17: High | H17: FE Dev | I17: Not Started | J17: 46158 | K17: 46158 | L17: 0.5 | M17: =IF(I17="Done",1,IF(I17="Review",0.8,IF(I17="In Progress",0.5,0))) | N17: T012 | O17: Video placeholder
A18: T014 | B18: Sprint 2 | C18: Vocab | D18: Vocab Block | E18: Tạo component từ vựng | F18: Hiển thị 3-5 từ: kanji/kana, nghĩa Việt, phiên âm, nút audio. | G18: High | H18: FE Dev | I18: Not Started | J18: 46159 | K18: 46159 | L18: 1 | M18: =IF(I18="Done",1,IF(I18="Review",0.8,IF(I18="In Progress",0.5,0))) | N18: T012 | O18: Vocab component
A19: T015 | B19: Sprint 2 | C19: Pattern | D19: Pattern Block | E19: Tạo component mẫu câu | F19: Mẫu câu cốt lõi + 2-3 biến thể theo tình huống. | G19: High | H19: FE Dev | I19: Not Started | J19: 46160 | K19: 46160 | L19: 1 | M19: =IF(I19="Done",1,IF(I19="Review",0.8,IF(I19="In Progress",0.5,0))) | N19: T012 | O19: Pattern component
A20: T016 | B20: Sprint 2 | C20: Example | D20: Example Block | E20: Tạo component ví dụ đầy đủ | F20: Email hoặc hội thoại mẫu có chú thích phần quan trọng. | G20: High | H20: FE Dev | I20: Not Started | J20: 46161 | K20: 46161 | L20: 1 | M20: =IF(I20="Done",1,IF(I20="Review",0.8,IF(I20="In Progress",0.5,0))) | N20: T012 | O20: Example component
A21: T017 | B21: Sprint 2 | C21: Practice | D21: Practice Block | E21: Tạo khung bài luyện điền từ | F21: HTML input, nút kiểm tra, vùng feedback. | G21: Medium | H21: FE Dev | I21: Not Started | J21: 46162 | K21: 46162 | L21: 0.75 | M21: =IF(I21="Done",1,IF(I21="Review",0.8,IF(I21="In Progress",0.5,0))) | N21: T012 | O21: Practice HTML
A22: T018 | B22: Sprint 2 | C22: Lesson Nav | D22: Lesson Navigation | E22: Tạo điều hướng bài học | F22: Nút bài trước, bài tiếp theo, quay lại module. | G22: Medium | H22: FE Dev | I22: Not Started | J22: 46163 | K22: 46163 | L22: 0.5 | M22: =IF(I22="Done",1,IF(I22="Review",0.8,IF(I22="In Progress",0.5,0))) | N22: T012 | O22: Lesson nav
A23: T019 | B23: Sprint 2 | C23: Lesson 01 | D23: stage2/email/lesson-01.html | E23: Tạo bài Email 01 | F23: Chủ đề: Xin chào khi join dự án mới. | G23: High | H23: Content | I23: Not Started | J23: 46164 | K23: 46165 | L23: 1.5 | M23: =IF(I23="Done",1,IF(I23="Review",0.8,IF(I23="In Progress",0.5,0))) | N23: T011 | O23: Lesson 01 content
A24: T020 | B24: Sprint 2 | C24: Lesson 01 | D24: stage2/email/lesson-01.html | E24: Gắn nội dung vào template | F24: Đưa Hero, Vocab, Pattern, Example, Practice vào HTML. | G24: High | H24: FE Dev | I24: Not Started | J24: 46166 | K24: 46166 | L24: 1 | M24: =IF(I24="Done",1,IF(I24="Review",0.8,IF(I24="In Progress",0.5,0))) | N24: T019 | O24: Lesson 01 page
A25: T021 | B25: Sprint 2 | C25: QA | D25: Lesson QA | E25: Kiểm tra lesson mẫu | F25: Kiểm tra hiển thị mobile, link, font Nhật-Việt, spacing. | G25: Medium | H25: QA | I25: Not Started | J25: 46167 | K25: 46167 | L25: 0.5 | M25: =IF(I25="Done",1,IF(I25="Review",0.8,IF(I25="In Progress",0.5,0))) | N25: T020 | O25: QA note
A26: T022 | B26: Sprint 3 | C26: Progress | D26: progress.js | E26: Tạo hàm markLessonComplete | F26: Lưu lessonId vào LocalStorage khi học viên bấm hoàn thành. | G26: High | H26: FE Dev | I26: Not Started | J26: 46168 | K26: 46168 | L26: 0.75 | M26: =IF(I26="Done",1,IF(I26="Review",0.8,IF(I26="In Progress",0.5,0))) | O26: markLessonComplete
A27: T023 | B27: Sprint 3 | C27: Progress | D27: progress.js | E27: Tạo hàm isLessonComplete | F27: Kiểm tra bài học đã hoàn thành chưa. | G27: High | H27: FE Dev | I27: Not Started | J27: 46169 | K27: 46169 | L27: 0.5 | M27: =IF(I27="Done",1,IF(I27="Review",0.8,IF(I27="In Progress",0.5,0))) | N27: T022 | O27: isLessonComplete
A28: T024 | B28: Sprint 3 | C28: Progress | D28: progress.js | E28: Tạo hàm getCompletedLessons | F28: Đọc danh sách bài đã hoàn thành từ LocalStorage. | G28: High | H28: FE Dev | I28: Not Started | J28: 46170 | K28: 46170 | L28: 0.5 | M28: =IF(I28="Done",1,IF(I28="Review",0.8,IF(I28="In Progress",0.5,0))) | N28: T022 | O28: getCompletedLessons
A29: T025 | B29: Sprint 3 | C29: Progress | D29: progress.js | E29: Tạo hàm calculateProgress | F29: Tính % hoàn thành dựa trên tổng lessonIds. | G29: High | H29: FE Dev | I29: Not Started | J29: 46171 | K29: 46171 | L29: 0.75 | M29: =IF(I29="Done",1,IF(I29="Review",0.8,IF(I29="In Progress",0.5,0))) | N29: T023,T024 | O29: calculateProgress
A30: T026 | B30: Sprint 3 | C30: Progress UI | D30: Lesson Page | E30: Gắn nút Đánh dấu đã học | F30: Button đổi trạng thái sau khi click, tránh click lặp. | G30: High | H30: FE Dev | I30: Not Started | J30: 46172 | K30: 46172 | L30: 0.75 | M30: =IF(I30="Done",1,IF(I30="Review",0.8,IF(I30="In Progress",0.5,0))) | N30: T022,T020 | O30: Complete button
A31: T027 | B31: Sprint 3 | C31: Progress UI | D31: Module Page | E31: Hiển thị progress module | F31: Ở trang module, tính số bài đã hoàn thành / tổng bài. | G31: High | H31: FE Dev | I31: Not Started | J31: 46173 | K31: 46173 | L31: 1 | M31: =IF(I31="Done",1,IF(I31="Review",0.8,IF(I31="In Progress",0.5,0))) | N31: T025 | O31: Module progress
A32: T028 | B32: Sprint 3 | C32: Progress UI | D32: Stage Page | E32: Hiển thị progress stage | F32: Ở Japanese Hub/Stage card, hiển thị % học tập. | G32: Medium | H32: FE Dev | I32: Not Started | J32: 46174 | K32: 46174 | L32: 1 | M32: =IF(I32="Done",1,IF(I32="Review",0.8,IF(I32="In Progress",0.5,0))) | N32: T025,T027 | O32: Stage progress
A33: T029 | B33: Sprint 3 | C33: Progress | D33: Reset Progress | E33: Tạo nút reset progress | F33: Cho phép xóa tiến độ local để test hoặc học lại. | G33: Low | H33: FE Dev | I33: Not Started | J33: 46175 | K33: 46175 | L33: 0.5 | M33: =IF(I33="Done",1,IF(I33="Review",0.8,IF(I33="In Progress",0.5,0))) | N33: T024 | O33: Reset button
A34: T030 | B34: Sprint 3 | C34: Continue | D34: Continue Learning | E34: Gợi ý bài tiếp theo | F34: Tự tìm lesson đầu tiên chưa hoàn thành trong Stage 2. | G34: Medium | H34: FE Dev | I34: Not Started | J34: 46176 | K34: 46176 | L34: 1 | M34: =IF(I34="Done",1,IF(I34="Review",0.8,IF(I34="In Progress",0.5,0))) | N34: T024 | O34: Continue CTA
A35: T031 | B35: Sprint 3 | C35: QA | D35: Progress QA | E35: Test LocalStorage | F35: Test refresh page, close/open browser, reset progress. | G35: Medium | H35: QA | I35: Not Started | J35: 46177 | K35: 46177 | L35: 0.5 | M35: =IF(I35="Done",1,IF(I35="Review",0.8,IF(I35="In Progress",0.5,0))) | N35: T026,T027,T028,T029,T030 | O35: QA note
A36: T032 | B36: Sprint 4 | C36: Quiz | D36: quiz.js | E36: Tạo initQuiz | F36: Render câu hỏi trắc nghiệm từ data JS. | G36: High | H36: FE Dev | I36: Not Started | J36: 46178 | K36: 46178 | L36: 1 | M36: =IF(I36="Done",1,IF(I36="Review",0.8,IF(I36="In Progress",0.5,0))) | O36: initQuiz
A37: T033 | B37: Sprint 4 | C37: Quiz | D37: quiz.js | E37: Tạo selectAnswer | F37: Bắt sự kiện chọn đáp án, khóa đáp án sau khi chọn. | G37: High | H37: FE Dev | I37: Not Started | J37: 46179 | K37: 46179 | L37: 0.75 | M37: =IF(I37="Done",1,IF(I37="Review",0.8,IF(I37="In Progress",0.5,0))) | N37: T032 | O37: selectAnswer
A38: T034 | B38: Sprint 4 | C38: Quiz | D38: quiz.js | E38: Tạo instant feedback | F38: Hiển thị đúng/sai và giải thích ngắn ngay sau khi chọn. | G38: High | H38: FE Dev | I38: Not Started | J38: 46180 | K38: 46180 | L38: 0.75 | M38: =IF(I38="Done",1,IF(I38="Review",0.8,IF(I38="In Progress",0.5,0))) | N38: T033 | O38: Feedback
A39: T035 | B39: Sprint 4 | C39: Quiz | D39: quiz.js | E39: Tạo calculateQuizScore | F39: Tính điểm quiz theo số câu đúng. | G39: High | H39: FE Dev | I39: Not Started | J39: 46181 | K39: 46181 | L39: 0.5 | M39: =IF(I39="Done",1,IF(I39="Review",0.8,IF(I39="In Progress",0.5,0))) | N39: T033 | O39: Score function
A40: T036 | B40: Sprint 4 | C40: Quiz | D40: quiz.js | E40: Tạo saveQuizScore | F40: Lưu score quiz vào LocalStorage. | G40: Medium | H40: FE Dev | I40: Not Started | J40: 46182 | K40: 46182 | L40: 0.5 | M40: =IF(I40="Done",1,IF(I40="Review",0.8,IF(I40="In Progress",0.5,0))) | N40: T035 | O40: Save score
A41: T037 | B41: Sprint 4 | C41: Quiz | D41: quiz.js | E41: Tạo retryQuiz | F41: Cho phép làm lại quiz. | G41: Medium | H41: FE Dev | I41: Not Started | J41: 46183 | K41: 46183 | L41: 0.5 | M41: =IF(I41="Done",1,IF(I41="Review",0.8,IF(I41="In Progress",0.5,0))) | N41: T036 | O41: Retry quiz
...

Sheet Dashboard
A1: Senpai MVP — Dashboard
A2: Theo dõi tổng quan task coding, sprint, trạng thái và tiến độ MVP
A4: Tổng task | B4: =COUNTA('Task Plan'!A5:A65) | D4: Sprint | E4: Scope chính | F4: Task | G4: Done | H4: In Progress | I4: Blocked | J4: Progress
A5: Done | B5: =COUNTIF('Task Plan'!I5:I65,"Done") | D5: Sprint 1 | E5: Khung website / deploy lần 1 | F5: =COUNTIF('Task Plan'!B5:B65,D5) | G5: =COUNTIFS('Task Plan'!B5:B65,D5,'Task Plan'!I5:I65,"Done") | H5: =COUNTIFS('Task Plan'!B5:B65,D5,'Task Plan'!I5:I65,"In Progress") | I5: =COUNTIFS('Task Plan'!B5:B65,D5,'Task Plan'!I5:I65,"Blocked") | J5: =IFERROR(AVERAGEIF('Task Plan'!B5:B65,D5,'Task Plan'!M5:M65),0)
A6: In Progress | B6: =COUNTIF('Task Plan'!I5:I65,"In Progress") | D6: Sprint 2 | E6: Lesson template + Lesson 01 | F6: =COUNTIF('Task Plan'!B5:B65,D6) | G6: =COUNTIFS('Task Plan'!B5:B65,D6,'Task Plan'!I5:I65,"Done") | H6: =COUNTIFS('Task Plan'!B5:B65,D6,'Task Plan'!I5:I65,"In Progress") | I6: =COUNTIFS('Task Plan'!B5:B65,D6,'Task Plan'!I5:I65,"Blocked") | J6: =IFERROR(AVERAGEIF('Task Plan'!B5:B65,D6,'Task Plan'!M5:M65),0)
A7: Blocked | B7: =COUNTIF('Task Plan'!I5:I65,"Blocked") | D7: Sprint 3 | E7: Progress tracking LocalStorage | F7: =COUNTIF('Task Plan'!B5:B65,D7) | G7: =COUNTIFS('Task Plan'!B5:B65,D7,'Task Plan'!I5:I65,"Done") | H7: =COUNTIFS('Task Plan'!B5:B65,D7,'Task Plan'!I5:I65,"In Progress") | I7: =COUNTIFS('Task Plan'!B5:B65,D7,'Task Plan'!I5:I65,"Blocked") | J7: =IFERROR(AVERAGEIF('Task Plan'!B5:B65,D7,'Task Plan'!M5:M65),0)
A8: Tiến độ TB | B8: =AVERAGE('Task Plan'!M5:M65) | D8: Sprint 4 | E8: Quiz / Practice tương tác | F8: =COUNTIF('Task Plan'!B5:B65,D8) | G8: =COUNTIFS('Task Plan'!B5:B65,D8,'Task Plan'!I5:I65,"Done") | H8: =COUNTIFS('Task Plan'!B5:B65,D8,'Task Plan'!I5:I65,"In Progress") | I8: =COUNTIFS('Task Plan'!B5:B65,D8,'Task Plan'!I5:I65,"Blocked") | J8: =IFERROR(AVERAGEIF('Task Plan'!B5:B65,D8,'Task Plan'!M5:M65),0)
A9: Tổng Est. Days | B9: =SUM('Task Plan'!L5:L65) | D9: Sprint 5 | E9: Vocabulary / Flashcard / Phrase Bank | F9: =COUNTIF('Task Plan'!B5:B65,D9) | G9: =COUNTIFS('Task Plan'!B5:B65,D9,'Task Plan'!I5:I65,"Done") | H9: =COUNTIFS('Task Plan'!B5:B65,D9,'Task Plan'!I5:I65,"In Progress") | I9: =COUNTIFS('Task Plan'!B5:B65,D9,'Task Plan'!I5:I65,"Blocked") | J9: =IFERROR(AVERAGEIF('Task Plan'!B5:B65,D9,'Task Plan'!M5:M65),0)
D10: Sprint 6 | E10: Polish MVP / deploy demo | F10: =COUNTIF('Task Plan'!B5:B65,D10) | G10: =COUNTIFS('Task Plan'!B5:B65,D10,'Task Plan'!I5:I65,"Done") | H10: =COUNTIFS('Task Plan'!B5:B65,D10,'Task Plan'!I5:I65,"In Progress") | I10: =COUNTIFS('Task Plan'!B5:B65,D10,'Task Plan'!I5:I65,"Blocked") | J10: =IFERROR(AVERAGEIF('Task Plan'!B5:B65,D10,'Task Plan'!M5:M65),0)
A12: Status | B12: Count | D12: Priority | E12: Count
A13: Not Started | B13: =COUNTIF('Task Plan'!I5:I65,A13) | D13: High | E13: =COUNTIF('Task Plan'!G5:G65,D13)
A14: In Progress | B14: =COUNTIF('Task Plan'!I5:I65,A14) | D14: Medium | E14: =COUNTIF('Task Plan'!G5:G65,D14)
A15: Review | B15: =COUNTIF('Task Plan'!I5:I65,A15) | D15: Low | E15: =COUNTIF('Task Plan'!G5:G65,D15)
A16: Done | B16: =COUNTIF('Task Plan'!I5:I65,A16)
A17: Blocked | B17: =COUNTIF('Task Plan'!I5:I65,A17)

Sheet Content Backlog
A1: Senpai — Content Backlog
A3: Stage | B3: Module | C3: Lesson ID | D3: Lesson Title | E3: Scenario | F3: Core Pattern | G3: Asset Status | H3: Priority | I3: Notes
A4: Stage 2 | B4: Email | C4: L2-EMAIL-01 | D4: Xin chào khi join dự án mới | E4: Dev/BA/PM mới vào dự án Nhật cần gửi lời chào ngắn gọn. | F4: お世話になります / よろしくお願いいたします | G4: MVP | H4: High | I4: Bài mẫu đầu tiên để chuẩn hóa template.
A5: Stage 2 | B5: Meeting | C5: L2-MEET-01 | D5: Khi không hiểu ý khách trong meeting | E5: Nghe khách giải thích spec nhưng chưa hiểu rõ điểm cần xác nhận. | F5: 恐れ入りますが、もう一度ご説明いただけますでしょうか | G5: MVP | H5: High | I5: Nên có hội thoại ngắn + practice chọn cách hỏi lại.
A6: Stage 2 | B6: Reporting | C6: L2-REPORT-01 | D6: Báo cáo tiến độ và báo delay | E6: Báo tiến độ tuần, nêu việc xong/chưa xong và lý do chậm. | F6: 現在、〇〇まで完了しております / 少し遅れております | G6: MVP | H6: High | I6: Rất sát thực tế dự án offshore.
A7: Stage 2 | B7: Email | C7: L2-EMAIL-02 | D7: Xác nhận yêu cầu sau meeting | E7: Tóm tắt lại nội dung đã hiểu và hỏi khách confirm. | F7: 認識に相違がないかご確認お願いいたします | G7: Next | H7: Medium | I7: Dùng cho PM/BA/Comtor.
A8: Stage 2 | B8: Trouble | C8: L2-TROUBLE-01 | D8: Báo lỗi phát sinh trên production | E8: Báo lỗi, ảnh hưởng, nguyên nhân tạm thời, hướng xử lý. | F8: 原因を調査中です / 対応完了後、改めてご報告いたします | G8: Next | H8: High | I8: Có thể đưa vào Stage 3 sau.
A9: Stage 2 | B9: Meeting | C9: L2-MEET-02 | D9: Cách xin thêm thời gian suy nghĩ | E9: Chưa thể trả lời ngay trong meeting, cần xin kiểm tra rồi phản hồi. | F9: 確認してから回答いたします | G9: Next | H9: Medium | I9: Tình huống phổ biến với Dev.
A10: Stage 3 | B10: Trouble | C10: L3-TROUBLE-01 | D10: Xin lỗi khi deploy gây lỗi | E10: Giải thích sự cố, xin lỗi, đưa hướng khắc phục và phòng ngừa. | F10: ご迷惑をおかけして申し訳ございません | G10: Future | H10: High | I10: Nên phát triển khi qua stage nâng cao.
A11: Stage 3 | B11: Negotiation | C11: L3-NEG-01 | D11: Đàm phán deadline mềm | E11: Khách yêu cầu gấp, cần giải thích rủi ro và đề xuất phương án. | F11: 品質を担保するため、〇日ほどいただけますでしょうか | G11: Future | H11: Medium | I11: Quan trọng cho PM/BRSE.
